{"name": "test_another_failed", "status": "failed", "statusDetails": {"message": "AssertionError: assert 1 == 2", "trace": "@pytest.mark.fail\n    def test_another_failed():\n>       assert 1 == 2\nE       assert 1 == 2\n\npytest\\tests\\users\\test_users.py:33: AssertionError"}, "start": 1755224403237, "stop": 1755224403237, "uuid": "8db46e6f-3688-4f18-84dd-ff7f6ac9f46f", "historyId": "58aac59f99684b4dced31fc07c7cc6a0", "testCaseId": "58aac59f99684b4dced31fc07c7cc6a0", "fullName": "pytest.tests.users.test_users#test_another_failed", "labels": [{"name": "tag", "value": "fail"}, {"name": "parentSuite", "value": "pytest.tests.users"}, {"name": "suite", "value": "test_users"}, {"name": "host", "value": "дочь"}, {"name": "thread", "value": "8968-MainThread"}, {"name": "framework", "value": "pytest"}, {"name": "language", "value": "cpython3"}, {"name": "package", "value": "pytest.tests.users.test_users"}], "titlePath": ["pytest", "tests", "users", "test_users.py"]}